Workbook
Name ENV_CODE: '1 Setup'!$B$14:$B$21
Name ENV_LANDSCAPE: '1 Setup'!$D$14:$D$21
Name ENV_SCOPE: '1 Setup'!$E$14:$E$21
Name ENV_KAFKA: '1 Setup'!$F$14:$F$21
Name ENV_SEARCH: '1 Setup'!$G$14:$G$21
Name KD_ENV: '3 Kafka Demand'!$A$7:$A$14
Name KD_CLUSTER: '3 Kafka Demand'!$B$7:$B$14
Name KD_LAND: '3 Kafka Demand'!$C$7:$C$14
Name KD_RANK: '3 Kafka Demand'!$D$7:$D$14
Name KD_STATUS: '3 Kafka Demand'!$E$7:$E$14
Name KD_MPARTS: '3 Kafka Demand'!$F$7:$F$14
Name KD_QPS: '3 Kafka Demand'!$G$7:$G$14
Name KD_TOPICS: '3 Kafka Demand'!$H$7:$H$14
Name KD_PPT: '3 Kafka Demand'!$I$7:$I$14
Name KD_PARTS: '3 Kafka Demand'!$J$7:$J$14
Name KD_COMPACT: '3 Kafka Demand'!$K$7:$K$14
Name KD_MSGS: '3 Kafka Demand'!$L$7:$L$14
Name KD_BYTES: '3 Kafka Demand'!$M$7:$M$14
Name KD_MIN: '3 Kafka Demand'!$N$7:$N$14
Name KD_IN: '3 Kafka Demand'!$O$7:$O$14
Name KD_FAN: '3 Kafka Demand'!$P$7:$P$14
Name KD_MOUT: '3 Kafka Demand'!$Q$7:$Q$14
Name KD_OUT: '3 Kafka Demand'!$R$7:$R$14
Name KD_DAY: '3 Kafka Demand'!$S$7:$S$14
Name KD_MGIB: '3 Kafka Demand'!$T$7:$T$14
Name KD_GIB: '3 Kafka Demand'!$U$7:$U$14
Name KD_GIBR: '3 Kafka Demand'!$V$7:$V$14
Name KD_RET: '3 Kafka Demand'!$W$7:$W$14
Name KD_COMP: '3 Kafka Demand'!$X$7:$X$14
Name KD_STORE: '3 Kafka Demand'!$Y$7:$Y$14
Name KD_CONN: '3 Kafka Demand'!$Z$7:$Z$14
Name KD_REQ: '3 Kafka Demand'!$AA$7:$AA$14
Name KD_MSGMAX: '3 Kafka Demand'!$AB$7:$AB$14
Name KD_NOTES: '3 Kafka Demand'!$AC$7:$AC$14
Name SD_ENV: '5 Search Demand'!$A$7:$A$14
Name SD_SVC: '5 Search Demand'!$B$7:$B$14
Name SD_LAND: '5 Search Demand'!$C$7:$C$14
Name SD_RANK: '5 Search Demand'!$D$7:$D$14
Name SD_STATUS: '5 Search Demand'!$E$7:$E$14
Name SD_GB: '5 Search Demand'!$F$7:$F$14
Name SD_DOCS: '5 Search Demand'!$G$7:$G$14
Name SD_IDX: '5 Search Demand'!$H$7:$H$14
Name SD_PRI: '5 Search Demand'!$I$7:$I$14
Name SD_GROW: '5 Search Demand'!$J$7:$J$14
Name SD_YRS: '5 Search Demand'!$K$7:$K$14
Name SD_TMP: '5 Search Demand'!$L$7:$L$14
Name SD_FGB: '5 Search Demand'!$M$7:$M$14
Name SD_FDOCS: '5 Search Demand'!$N$7:$N$14
Name SD_PRIM: '5 Search Demand'!$O$7:$O$14
Name SD_NOTES: '5 Search Demand'!$P$7:$P$14
Name KS_CHECKS: '6 Kafka Sizing'!$F$106:$K$120
Name SZ_CHECKS: '7 Search Sizing'!$F$80:$K$92
Name P_KAFKA_PARTS: 'Ref_Data'!$D$5
Name P_KAFKA_DEV_N: 'Ref_Data'!$D$6
Name P_KAFKA_DEV_CPU: 'Ref_Data'!$D$7
Name P_KAFKA_DEV_RAM: 'Ref_Data'!$D$8
Name P_KAFKA_DEV_DISK: 'Ref_Data'!$D$9
Name P_KAFKA_PRD_N: 'Ref_Data'!$D$10
Name P_KAFKA_PRD_CPU: 'Ref_Data'!$D$11
Name P_KAFKA_PRD_RAM: 'Ref_Data'!$D$12

Sheet Cover
B2: Pega Platform '26 on Azure AKS
B3: Kafka and OpenSearch sizing workbook
B4: Sizes Confluent Cloud clusters and managed OpenSearch services for the Pega '26 externalised Kafka and search services, from inputs the customer collects, using Pega's published recommendations and the providers' published limits.
B6: WORKED EXAMPLE: illustrative inputs only
B7: Version | C7: 1.0
B8: Date | C8: 6 October 2026
B9: Customer | C9: =IF('1 Setup'!C4="","(enter on Setup)",'1 Setup'!C4)
B10: Status | C10: ='1 Setup'!C11
B11: Evidence checked | C11: 6 Oct 2026
B13: Results summary
B14: Kafka cluster | C14: Environments | D14: Type | E14: Units | F14: Sized by | G14: Checks
B15: ='6 Kafka Sizing'!F8 | C15: ='6 Kafka Sizing'!F7 | D15: ='6 Kafka Sizing'!F67 | E15: =IF('6 Kafka Sizing'!F70=0,"-",'6 Kafka Sizing'!F70&" "&'6 Kafka Sizing'!F69) | F15: ='6 Kafka Sizing'!F79 | G15: ='10 Checks'!G5
B16: ='6 Kafka Sizing'!G8 | C16: ='6 Kafka Sizing'!G7 | D16: ='6 Kafka Sizing'!G67 | E16: =IF('6 Kafka Sizing'!G70=0,"-",'6 Kafka Sizing'!G70&" "&'6 Kafka Sizing'!G69) | F16: ='6 Kafka Sizing'!G79 | G16: ='10 Checks'!G6
B17: ='6 Kafka Sizing'!H8 | C17: ='6 Kafka Sizing'!H7 | D17: ='6 Kafka Sizing'!H67 | E17: =IF('6 Kafka Sizing'!H70=0,"-",'6 Kafka Sizing'!H70&" "&'6 Kafka Sizing'!H69) | F17: ='6 Kafka Sizing'!H79 | G17: ='10 Checks'!G7
B18: ='6 Kafka Sizing'!I8 | C18: ='6 Kafka Sizing'!I7 | D18: ='6 Kafka Sizing'!I67 | E18: =IF('6 Kafka Sizing'!I70=0,"-",'6 Kafka Sizing'!I70&" "&'6 Kafka Sizing'!I69) | F18: ='6 Kafka Sizing'!I79 | G18: ='10 Checks'!G8
B19: ='6 Kafka Sizing'!J8 | C19: ='6 Kafka Sizing'!J7 | D19: ='6 Kafka Sizing'!J67 | E19: =IF('6 Kafka Sizing'!J70=0,"-",'6 Kafka Sizing'!J70&" "&'6 Kafka Sizing'!J69) | F19: ='6 Kafka Sizing'!J79 | G19: ='10 Checks'!G9
B20: ='6 Kafka Sizing'!K8 | C20: ='6 Kafka Sizing'!K7 | D20: ='6 Kafka Sizing'!K67 | E20: =IF('6 Kafka Sizing'!K70=0,"-",'6 Kafka Sizing'!K70&" "&'6 Kafka Sizing'!K69) | F20: ='6 Kafka Sizing'!K79 | G20: ='10 Checks'!G10
B22: Search service | C22: Environments | D22: Data nodes | E22: Managers | F22: Sized by | G22: Checks
B23: ='7 Search Sizing'!F8 | C23: ='7 Search Sizing'!F7 | D23: =IF('7 Search Sizing'!F56=0,"-",'7 Search Sizing'!F56&" x "&'7 Search Sizing'!F40&" vCPU / "&'7 Search Sizing'!F41&" GB / "&'7 Search Sizing'!F42&" GB") | E23: =IF('7 Search Sizing'!F61=0,"-",'7 Search Sizing'!F61&" x "&'7 Search Sizing'!F62&" vCPU / "&'7 Search Sizing'!F63&" GB") | F23: ='7 Search Sizing'!F57 | G23: ='10 Checks'!G11
B24: ='7 Search Sizing'!G8 | C24: ='7 Search Sizing'!G7 | D24: =IF('7 Search Sizing'!G56=0,"-",'7 Search Sizing'!G56&" x "&'7 Search Sizing'!G40&" vCPU / "&'7 Search Sizing'!G41&" GB / "&'7 Search Sizing'!G42&" GB") | E24: =IF('7 Search Sizing'!G61=0,"-",'7 Search Sizing'!G61&" x "&'7 Search Sizing'!G62&" vCPU / "&'7 Search Sizing'!G63&" GB") | F24: ='7 Search Sizing'!G57 | G24: ='10 Checks'!G12
B25: ='7 Search Sizing'!H8 | C25: ='7 Search Sizing'!H7 | D25: =IF('7 Search Sizing'!H56=0,"-",'7 Search Sizing'!H56&" x "&'7 Search Sizing'!H40&" vCPU / "&'7 Search Sizing'!H41&" GB / "&'7 Search Sizing'!H42&" GB") | E25: =IF('7 Search Sizing'!H61=0,"-",'7 Search Sizing'!H61&" x "&'7 Search Sizing'!H62&" vCPU / "&'7 Search Sizing'!H63&" GB") | F25: ='7 Search Sizing'!H57 | G25: ='10 Checks'!G13
B26: ='7 Search Sizing'!I8 | C26: ='7 Search Sizing'!I7 | D26: =IF('7 Search Sizing'!I56=0,"-",'7 Search Sizing'!I56&" x "&'7 Search Sizing'!I40&" vCPU / "&'7 Search Sizing'!I41&" GB / "&'7 Search Sizing'!I42&" GB") | E26: =IF('7 Search Sizing'!I61=0,"-",'7 Search Sizing'!I61&" x "&'7 Search Sizing'!I62&" vCPU / "&'7 Search Sizing'!I63&" GB") | F26: ='7 Search Sizing'!I57 | G26: ='10 Checks'!G14
B27: ='7 Search Sizing'!J8 | C27: ='7 Search Sizing'!J7 | D27: =IF('7 Search Sizing'!J56=0,"-",'7 Search Sizing'!J56&" x "&'7 Search Sizing'!J40&" vCPU / "&'7 Search Sizing'!J41&" GB / "&'7 Search Sizing'!J42&" GB") | E27: =IF('7 Search Sizing'!J61=0,"-",'7 Search Sizing'!J61&" x "&'7 Search Sizing'!J62&" vCPU / "&'7 Search Sizing'!J63&" GB") | F27: ='7 Search Sizing'!J57 | G27: ='10 Checks'!G15
B28: ='7 Search Sizing'!K8 | C28: ='7 Search Sizing'!K7 | D28: =IF('7 Search Sizing'!K56=0,"-",'7 Search Sizing'!K56&" x "&'7 Search Sizing'!K40&" vCPU / "&'7 Search Sizing'!K41&" GB / "&'7 Search Sizing'!K42&" GB") | E28: =IF('7 Search Sizing'!K61=0,"-",'7 Search Sizing'!K61&" x "&'7 Search Sizing'!K62&" vCPU / "&'7 Search Sizing'!K63&" GB") | F28: ='7 Search Sizing'!K57 | G28: ='10 Checks'!G16
B30: Colour key
C31: Input: the customer enters or confirms this value
C32: Worked out by formula: do not overwrite
C33: Result: carried to the summary and the provider request sheets
C34: Published reference value (Ref_Data)
C35: WARN: review before sending
C36: FAIL: must be resolved before sending
B38: Sheets
B39: Guide | C39: How to use the workbook and where each input comes from
B40: 1 Setup | C40: Programme details; environments and their cluster and service assignment
B41: 2 Kafka Clusters | C41: Kafka cluster requirements: SLA, networking, keys, growth and utilisation
B42: 3 Kafka Demand | C42: Kafka demand per environment: partitions, throughput, retention, connections
B43: 4 Search Services | C43: Search service requirements: high availability, zones, replicas, overheads
B44: 5 Search Demand | C44: Search demand per environment: data, documents, indexes, growth
B45: 6 Kafka Sizing | C45: Kafka calculation, step by step, with checks and explanation
B46: 7 Search Sizing | C46: Search calculation, step by step, with checks and explanation
...

Sheet Guide
A1: Guide: how to use this workbook
A2: Work through the numbered sheets in order. Hover over cells with a red corner for guidance and sources.
A4: Step | B4: Sheet | C4: What to do
A5: 1 | B5: Setup | C5: Enter the programme details. List the environments, choose each one's Pega landscape and assign it to a Kafka cluster (K1 to K6) and a search service (S1 to S6).
A6: 2 | B6: Kafka Clusters | C6: For each cluster in use, choose the SLA, private networking, self-managed keys, preferred type, growth allowance and target utilisation.
A7: 3 | B7: Kafka Demand | C7: For each environment, enter partitions (measured, or queue processors and topics), peak throughput, daily volume, retention, connections, requests and largest message. Set the input status to Measured or Estimated.
A8: 4 | B8: Search Services | C8: For each service in use, choose high availability, zones and replicas, and enter the provider's storage overhead when known.
A9: 5 | B9: Search Demand | C9: For each environment, enter searchable data, documents, indexes, growth and planning period.
A10: 6 | B10: Checks | C10: Resolve every FAIL and review every WARN. Read the explanation at the foot of the two sizing sheets.
A11: 7 | B11: Request sheets | C11: Send the Confluent Request sheet to Confluent and the Search Request sheet to the OpenSearch provider, with the questions on each sheet. Record their answers in the Notes rows and update the inputs.
A12: 8 | B12: After go-live in DEV | C12: Replace estimates with measured figures from the first DEV build on the new services and recalculate before sizing the higher environments.
A14: Where each input comes from
B15: Input | C15: Pega 8.8 today (embedded services) | D15: Pega '26 DEV on the new services | E15: Notes
B16: Leader partitions | C16: Stream service landing page in Pega 8.8 (partitions per topic) [P5] | D16: Confluent topic list for the DEV cluster after the first Pega '26 start-up | E16: Queue processor topics have six partitions by default [P3].
B17: Queue processors and topics | C17: Admin Studio, Queue processors; Dev Studio, Stream data sets | D17: Confluent topic list | E17: Include the system pulse topic (6 partitions) [P6] and the messaging topics that replace Hazelcast from Pega '25 [P8]; these do not exist on 8.8.
B18: Peak messages and size | C18: Stream service monitoring in Pega 8.8, or application estimates | D18: Confluent Cloud cluster metrics: received records and received bytes at peak | E18: Use the busiest hour of a normal business day plus any batch window.
B19: Peak read and fan-out | C19: Number of consumers per topic | D19: Confluent Cloud cluster metrics: sent bytes at peak | E19: Egress counts every read by every consumer group.
B20: Messages or GiB per day | C20: Application estimates | D20: Confluent Cloud cluster metrics: received bytes per day | E20: Drives ingress, egress and storage pricing [C2].
B21: Retention | C21: Design decision | D21: Topic retention.ms | E21: Confluent topic default is 7 days [C3].
B22: Client connections and requests | C22: Not available from embedded Kafka in a comparable form | D22: Confluent Cloud cluster metrics for the DEV cluster under test load | E22: Pega publishes no figure. Leave blank until measured; the checks show it as not assessed.
B23: Largest message | C23: Application design | D23: Producer errors in Pega logs if the limit is reached | E23: Pega default limit 5,000,000 bytes [P1].
B24: Searchable data and documents | C24: Current 8.8 search index size and document counts | D24: GET _cat/indices?v (pri.store.size and docs.count) after the first SRS build [A1] | E24: Enter primary size only; the workbook adds replicas.
B25: Indexes and primary shards | C25: Current search indexes | D25: GET _cat/indices?v after the first SRS build | E25: OpenSearch default is one primary shard per index [O2].
B26: Growth and planning period | C26: Business plans | D26: - | E26: Applied to both services.
A28: How the workbook sizes the services
B29: Kafka | C29: Demand from all environments on a cluster is added up. Each figure is raised by the growth allowance and divided by the target utilisation. For each Confluent type, the units needed are the largest of planned demand divided by the per-unit limit for ingress, egress, partitions, compacted partitions, connections and requests, and the minimum units for the SLA [C1]. The first type that meets the SLA, networking and key requirements and fits within its maximum is recommended, unless the customer forces a type. Pega's Table 1 and partitions-per-broker table give a self-managed reference for comparison [P1][P5].
B30: Search | C30: Pega's Default or Large profile gives the starting node sizes and counts [P2]. Storage is worked out with the AWS formula (replicas, indexing overhead, OS reserve and provider overhead) [A1]. The data-node count is the largest of: the Pega profile with the three-node HA rule, storage / disk per node, shards / 1,000 [O3], shards / (25 x heap) [A2], and replicas + 1 [O5]. With high availability it is rounded up to a multiple of the zone count [O1].
B31: Pricing | C31: Confluent bills capacity units per hour, ingress and egress per GiB and storage per GiB-hour after replication [C2]. The workbook gives these quantities per month for Confluent to price. The search provider prices the nodes on the Search Request sheet.

Sheet 1 Setup
A1: 1 Setup: programme details and environments
A2: Enter the programme details and the environments. Assign each environment to a Kafka cluster (K1 to K6) and a search service (S1 to S6).
B4: Customer
B5: Programme | C5: Pega 8.8 to Pega Platform '26 (26.1.1) clone and upgrade on Azure AKS
B6: Prepared by
B7: Date of inputs
B8: Azure region
B9: Target Pega version | C9: Pega Platform '26 (26.1.1)
B10: Source system | C10: Pega 8.8 with embedded Kafka (Stream service) and embedded search
B11: Workbook status | C11: Draft
A13: # | B13: Environment code | C13: Description | D13: Pega landscape | E13: In scope | F13: Kafka cluster | G13: Search service | H13: Notes
A14: E1 | B14: DEV | C14: Development | D14: Development | E14: Yes | F14: K1 | G14: S1
A15: E2 | B15: SIT | C15: System integration test | D15: Testing | E15: Yes | F15: K1 | G15: S1
A16: E3 | B16: UAT | C16: User acceptance test | D16: Testing | E16: Yes | F16: K1 | G16: S1
A17: E4 | B17: PERF | C17: Performance test | D17: Stage | E17: Yes | F17: K2 | G17: S2
A18: E5 | B18: PREPROD | C18: Pre-production | D18: Stage | E18: Yes | F18: K2 | G18: S2
A19: E6 | B19: PROD | C19: Production | D19: Production | E19: Yes | F19: K3 | G19: S3
A20: E7
A21: E8
B23: Environment assignment used in the delivered template follows runbook v2.3 Section 5 (option B): DEV, SIT and UAT share K1 and S1; PERF and PREPROD share K2 and S2; PROD has K3 and S3. Change it if the design changes.

Sheet 2 Kafka Clusters
A1: 2 Kafka clusters: requirements for each Confluent Cloud cluster
A2: One column per cluster. Only clusters with environments assigned on the Setup sheet are sized.
A4: Step | B4: Item | C4: Unit | D4: Guidance | E4: Ref | F4: K1 | G4: K2 | H4: K3 | I4: K4 | J4: K5 | K4: K6
A5: A. Identification
A6: KC.01 | B6: Cluster name | C6: text | D6: Name the customer will use with Confluent, for example cc-prd. | E6: - | F6: cc-np1 | G6: cc-np2 | H6: cc-prd
A7: KC.02 | B7: Azure region | C7: text | D7: Leave blank to use the region on the Setup sheet. | E7: -
A8: B. Service requirements (customer decisions)
A9: KC.03 | B9: Required availability SLA | C9: % | D9: 99.5 % is only offered on Basic. 99.9 % needs 1 eCKU on Standard or Enterprise; 99.99 % needs 2 eCKU. Dedicated gives 99.95 % single-zone or 99.99 % multi-zone (2 CKU or more). | E9: C1 | F9: 99.9% | G9: 99.99% | H9: 99.99% | I9: 99.99% | J9: 99.99% | K9: 99.99%
A10: KC.04 | B10: Private networking required | C10: Yes/No | D10: Yes if AKS must reach Kafka over Azure Private Link. Confluent positions Standard for public networking and Enterprise for private networking. | E10: C1 | F10: Yes | G10: Yes | H10: Yes | I10: Yes | J10: Yes | K10: Yes
A11: KC.05 | B11: Self-managed encryption keys (BYOK) | C11: Yes/No | D11: On Azure, self-managed keys are available on Dedicated and Enterprise only, and are fixed at cluster creation. | E11: C4 | F11: No | G11: No | H11: No | I11: No | J11: No | K11: No
A12: KC.06 | B12: Multi-zone required (Dedicated) | C12: Yes/No | D12: Applies only if Dedicated is chosen. Multi-zone needs at least 2 CKU and cannot be changed after creation. | E12: C1 | F12: Yes | G12: Yes | H12: Yes | I12: Yes | J12: Yes | K12: Yes
A13: KC.07 | B13: Preferred cluster type | C13: list | D13: Auto lets the workbook choose the first suitable type in the order Basic, Standard, Enterprise, Dedicated. Choose a type to force it; the checks show whether it meets the requirements. | E13: C1 | F13: Auto | G13: Auto | H13: Auto | I13: Auto | J13: Auto | K13: Auto
A14: KC.08 | B14: Confluent billing method | C14: list | D14: Sets the Dedicated purchase limit: 4 CKU with credit card, 24 CKU with invoice or marketplace billing. Higher limits are available by request. | E14: C1 | F14: Invoice | G14: Invoice | H14: Invoice | I14: Invoice | J14: Invoice | K14: Invoice
A15: C. Planning allowance (customer decisions)
A16: KC.09 | B16: Growth allowance over the planning period | C16: % | D16: Expected growth in partitions, throughput, connections and stored data. Pega publishes no growth figure; this is a business input. | E16: W | F16: 0.2 | G16: 0.2 | H16: 0.2 | I16: 0.2 | J16: 0.2 | K16: 0.2
A17: KC.10 | B17: Target maximum utilisation | C17: % | D17: Planned capacity = demand x (1 + growth) / target. 70 % matches the average CPU level at which Pega advises a bigger node for its stream service. Change it if your policy differs. | E17: P5 | F17: 0.7 | G17: 0.7 | H17: 0.7 | I17: 0.7 | J17: 0.7 | K17: 0.7
A18: KC.11 | B18: Notes | C18: text | D18: Decisions or assumptions for this cluster. | E18: -

Sheet 3 Kafka Demand
A1: 3 Kafka demand per environment
A2: One row per environment from the Setup sheet. Enter measured figures where available.
A5: Environment | E5: Partitions | K5: Peak throughput | S5: Daily volume and storage | Z5: Connections, requests and message size
A6: Environment | B6: Kafka cluster | C6: Pega landscape | D6: Landscape rank (1-4) | E6: Input status (list) | F6: Measured leader partitions (count) | G6: Queue processors (count) | H6: Other Pega topics (count) | I6: Partitions per topic (count) | J6: Leader partitions used (count) | K6: Of which compacted (count) | L6: Peak messages written per second (msg/s) | M6: Average message size (bytes) | N6: Measured peak write (MBps) | O6: Peak write used (MBps) | P6: Consumer fan-out (reads per write) | Q6: Measured peak read (MBps) | R6: Peak read used (MBps) | S6: Messages written per day (count) | T6: Measured GiB written per day (GiB) | U6: GiB written per day used (GiB) | V6: GiB read per day (GiB) | W6: Retention (hours) | X6: Compression ratio (x) | Y6: Stored GiB (before replication) (GiB) | Z6: Peak client connections (count) | AA6: Peak requests per second (req/s) | AB6: Largest message (bytes) | AC6: Notes
A7: =IF('1 Setup'!B14="","",'1 Setup'!B14) | B7: =IF(AND('1 Setup'!E14="Yes",'1 Setup'!F14<>""),'1 Setup'!F14,"") | C7: =IF('1 Setup'!D14="","",'1 Setup'!D14) | D7: =IFERROR(MATCH(C7,LANDSCAPES,0),0) | E7: Example | G7: 120 | H7: 30 | I7: 6 | J7: =IF(F7<>"",F7,(G7+H7)*I7) | K7: 0 | L7: 1000 | M7: 1000 | O7: =IF(N7<>"",N7,L7*M7/W_BYTES_MB) | P7: 2 | R7: =IF(Q7<>"",Q7,O7*P7) | S7: 20000000 | U7: =IF(T7<>"",T7,S7*M7/W_BYTES_GIB) | V7: =IF(AND(Q7<>"",N7<>"",N7>0),U7*Q7/N7,U7*P7) | W7: 168 | X7: 1 | Y7: =IF(W7="",0,U7*W7/24/IF(X7>0,X7,1)) | Z7: 600 | AA7: 1000 | AB7: 1000000 | AC7: Illustrative figures for the worked example. Replace with measured values.
A8: =IF('1 Setup'!B15="","",'1 Setup'!B15) | B8: =IF(AND('1 Setup'!E15="Yes",'1 Setup'!F15<>""),'1 Setup'!F15,"") | C8: =IF('1 Setup'!D15="","",'1 Setup'!D15) | D8: =IFERROR(MATCH(C8,LANDSCAPES,0),0) | E8: Example | G8: 120 | H8: 30 | I8: 6 | J8: =IF(F8<>"",F8,(G8+H8)*I8) | K8: 0 | L8: 1500 | M8: 1000 | O8: =IF(N8<>"",N8,L8*M8/W_BYTES_MB) | P8: 2 | R8: =IF(Q8<>"",Q8,O8*P8) | S8: 30000000 | U8: =IF(T8<>"",T8,S8*M8/W_BYTES_GIB) | V8: =IF(AND(Q8<>"",N8<>"",N8>0),U8*Q8/N8,U8*P8) | W8: 168 | X8: 1 | Y8: =IF(W8="",0,U8*W8/24/IF(X8>0,X8,1)) | Z8: 600 | AA8: 1200 | AB8: 1000000 | AC8: Illustrative figures for the worked example. Replace with measured values.
A9: =IF('1 Setup'!B16="","",'1 Setup'!B16) | B9: =IF(AND('1 Setup'!E16="Yes",'1 Setup'!F16<>""),'1 Setup'!F16,"") | C9: =IF('1 Setup'!D16="","",'1 Setup'!D16) | D9: =IFERROR(MATCH(C9,LANDSCAPES,0),0) | E9: Example | G9: 120 | H9: 30 | I9: 6 | J9: =IF(F9<>"",F9,(G9+H9)*I9) | K9: 0 | L9: 2000 | M9: 1000 | O9: =IF(N9<>"",N9,L9*M9/W_BYTES_MB) | P9: 2 | R9: =IF(Q9<>"",Q9,O9*P9) | S9: 40000000 | U9: =IF(T9<>"",T9,S9*M9/W_BYTES_GIB) | V9: =IF(AND(Q9<>"",N9<>"",N9>0),U9*Q9/N9,U9*P9) | W9: 168 | X9: 1 | Y9: =IF(W9="",0,U9*W9/24/IF(X9>0,X9,1)) | Z9: 800 | AA9: 1500 | AB9: 1000000 | AC9: Illustrative figures for the worked example. Replace with measured values.
A10: =IF('1 Setup'!B17="","",'1 Setup'!B17) | B10: =IF(AND('1 Setup'!E17="Yes",'1 Setup'!F17<>""),'1 Setup'!F17,"") | C10: =IF('1 Setup'!D17="","",'1 Setup'!D17) | D10: =IFERROR(MATCH(C10,LANDSCAPES,0),0) | E10: Example | G10: 120 | H10: 30 | I10: 6 | J10: =IF(F10<>"",F10,(G10+H10)*I10) | K10: 0 | L10: 8000 | M10: 1000 | O10: =IF(N10<>"",N10,L10*M10/W_BYTES_MB) | P10: 2 | R10: =IF(Q10<>"",Q10,O10*P10) | S10: 150000000 | U10: =IF(T10<>"",T10,S10*M10/W_BYTES_GIB) | V10: =IF(AND(Q10<>"",N10<>"",N10>0),U10*Q10/N10,U10*P10) | W10: 72 | X10: 1 | Y10: =IF(W10="",0,U10*W10/24/IF(X10>0,X10,1)) | Z10: 1500 | AA10: 4000 | AB10: 2000000 | AC10: Illustrative figures for the worked example. Replace with measured values.
A11: =IF('1 Setup'!B18="","",'1 Setup'!B18) | B11: =IF(AND('1 Setup'!E18="Yes",'1 Setup'!F18<>""),'1 Setup'!F18,"") | C11: =IF('1 Setup'!D18="","",'1 Setup'!D18) | D11: =IFERROR(MATCH(C11,LANDSCAPES,0),0) | E11: Example | G11: 120 | H11: 30 | I11: 6 | J11: =IF(F11<>"",F11,(G11+H11)*I11) | K11: 0 | L11: 4000 | M11: 1000 | O11: =IF(N11<>"",N11,L11*M11/W_BYTES_MB) | P11: 2 | R11: =IF(Q11<>"",Q11,O11*P11) | S11: 80000000 | U11: =IF(T11<>"",T11,S11*M11/W_BYTES_GIB) | V11: =IF(AND(Q11<>"",N11<>"",N11>0),U11*Q11/N11,U11*P11) | W11: 168 | X11: 1 | Y11: =IF(W11="",0,U11*W11/24/IF(X11>0,X11,1)) | Z11: 1500 | AA11: 3000 | AB11: 2000000 | AC11: Illustrative figures for the worked example. Replace with measured values.
A12: =IF('1 Setup'!B19="","",'1 Setup'!B19) | B12: =IF(AND('1 Setup'!E19="Yes",'1 Setup'!F19<>""),'1 Setup'!F19,"") | C12: =IF('1 Setup'!D19="","",'1 Setup'!D19) | D12: =IFERROR(MATCH(C12,LANDSCAPES,0),0) | E12: Example | G12: 120 | H12: 30 | I12: 6 | J12: =IF(F12<>"",F12,(G12+H12)*I12) | K12: 0 | L12: 8000 | M12: 1000 | O12: =IF(N12<>"",N12,L12*M12/W_BYTES_MB) | P12: 2 | R12: =IF(Q12<>"",Q12,O12*P12) | S12: 300000000 | U12: =IF(T12<>"",T12,S12*M12/W_BYTES_GIB) | V12: =IF(AND(Q12<>"",N12<>"",N12>0),U12*Q12/N12,U12*P12) | W12: 168 | X12: 1 | Y12: =IF(W12="",0,U12*W12/24/IF(X12>0,X12,1)) | Z12: 1800 | AA12: 4000 | AB12: 2000000 | AC12: Illustrative figures for the worked example. Replace with measured values.
A13: =IF('1 Setup'!B20="","",'1 Setup'!B20) | B13: =IF(AND('1 Setup'!E20="Yes",'1 Setup'!F20<>""),'1 Setup'!F20,"") | C13: =IF('1 Setup'!D20="","",'1 Setup'!D20) | D13: =IFERROR(MATCH(C13,LANDSCAPES,0),0) | I13: 6 | J13: =IF(F13<>"",F13,(G13+H13)*I13) | O13: =IF(N13<>"",N13,L13*M13/W_BYTES_MB) | P13: 1 | R13: =IF(Q13<>"",Q13,O13*P13) | U13: =IF(T13<>"",T13,S13*M13/W_BYTES_GIB) | V13: =IF(AND(Q13<>"",N13<>"",N13>0),U13*Q13/N13,U13*P13) | W13: 168 | X13: 1 | Y13: =IF(W13="",0,U13*W13/24/IF(X13>0,X13,1))
A14: =IF('1 Setup'!B21="","",'1 Setup'!B21) | B14: =IF(AND('1 Setup'!E21="Yes",'1 Setup'!F21<>""),'1 Setup'!F21,"") | C14: =IF('1 Setup'!D21="","",'1 Setup'!D21) | D14: =IFERROR(MATCH(C14,LANDSCAPES,0),0) | I14: 6 | J14: =IF(F14<>"",F14,(G14+H14)*I14) | O14: =IF(N14<>"",N14,L14*M14/W_BYTES_MB) | P14: 1 | R14: =IF(Q14<>"",Q14,O14*P14) | U14: =IF(T14<>"",T14,S14*M14/W_BYTES_GIB) | V14: =IF(AND(Q14<>"",N14<>"",N14>0),U14*Q14/N14,U14*P14) | W14: 168 | X14: 1 | Y14: =IF(W14="",0,U14*W14/24/IF(X14>0,X14,1))
A16: Yellow cells are inputs; grey cells are worked out. Hover over a column heading for guidance and the source. Where a measured figure is given it replaces the estimate beside it.

Sheet 4 Search Services
A1: 4 Search services: requirements for each managed OpenSearch service
A2: One column per service. Only services with environments assigned on the Setup sheet are sized.
A4: Step | B4: Item | C4: Unit | D4: Guidance | E4: Ref | F4: S1 | G4: S2 | H4: S3 | I4: S4 | J4: S5 | K4: S6
A5: A. Identification
A6: SS.01 | B6: Service name | C6: text | D6: Name the customer will use with the search provider, for example os-prd. | E6: - | F6: os-np1 | G6: os-np2 | H6: os-prd
A7: SS.02 | B7: Azure region | C7: text | D7: Leave blank to use the region on the Setup sheet. | E7: -
A8: B. Service requirements (customer decisions)
A9: SS.03 | B9: High availability required | C9: Yes/No | D9: Yes applies Pega's rule of at least three cluster manager nodes, three data nodes and three SRS pods. | E9: P2 | F9: Yes | G9: Yes | H9: Yes | I9: Yes | J9: Yes | K9: Yes
A10: SS.04 | B10: Availability zones | C10: count | D10: With high availability, data nodes are rounded up to a multiple of the zone count, as OpenSearch advises for three zones. | E10: O1 | F10: 3 | G10: 3 | H10: 3 | I10: 3 | J10: 3 | K10: 3
A11: SS.05 | B11: Replicas per primary shard | C11: count | D11: OpenSearch default is 1. Each replica is a full extra copy and is placed on a different node from its primary, so replicas + 1 data nodes are needed. For a single-node test service, as in Pega's test rows, set 0. | E11: O2, O5 | F11: 1 | G11: 1 | H11: 1 | I11: 1 | J11: 1 | K11: 1
A12: SS.06 | B12: Pega sizing profile | C12: list | D12: Auto picks Large when searchable data reaches the 2 TB of Pega's large example, otherwise Default. Choose Minimum, Default or Large to override. | E12: P2 | F12: Auto | G12: Auto | H12: Auto | I12: Auto | J12: Auto | K12: Auto
A13: C. Provider storage overheads (replace with the provider's figures)
A14: SS.07 | B14: Provider storage overhead | C14: % | D14: Space the provider reserves on each node. 20 % is the AWS OpenSearch Service figure (capped at 20 GiB per instance). Ask your provider for theirs. | E14: A1 | F14: 0.2 | G14: 0.2 | H14: 0.2 | I14: 0.2 | J14: 0.2 | K14: 0.2
A15: SS.08 | B15: Operating system reserved space | C15: % | D15: Linux reserves 5 % of the file system by default. | E15: A1 | F15: 0.05 | G15: 0.05 | H15: 0.05 | I15: 0.05 | J15: 0.05 | K15: 0.05
A16: SS.09 | B16: Indexing overhead | C16: % | D16: Index size on disk relative to the source data; often about 10 %. | E16: A1 | F16: 0.1 | G16: 0.1 | H16: 0.1 | I16: 0.1 | J16: 0.1 | K16: 0.1
A17: D. Data node size overrides (leave blank to use the Pega profile size)
A18: SS.10 | B18: Data node vCPU (override) | C18: vCPU | D18: Leave blank to use the Pega profile size. | E18: P2 | F18: 4
A19: SS.11 | B19: Data node RAM (override) | C19: GB | D19: Leave blank to use the Pega profile size. Java heap is taken as half of RAM. | E19: P2, O4 | F19: 16
A20: SS.12 | B20: Data node disk (override) | C20: GB | D20: Leave blank to use the Pega profile size. A larger disk can reduce the node count when storage drives it. | E20: P2
A21: E. Service options
A22: SS.13 | B22: Engine version offered by the provider | C22: list | D22: Pega supports OpenSearch 1.3, 2.15 and 2.19 with the search-n-reporting-service-os image; 2.15 is Pega's best practice. | E22: P2 | F22: OpenSearch 2.15 | G22: OpenSearch 2.15 | H22: OpenSearch 2.15 | I22: OpenSearch 2.15 | J22: OpenSearch 2.15 | K22: OpenSearch 2.15
A23: SS.14 | B23: Private connectivity required | C23: Yes/No | D23: For the provider request only. | E23: - | F23: Yes | G23: Yes | H23: Yes | I23: Yes | J23: Yes | K23: Yes
A24: SS.15 | B24: Customer-managed encryption key | C24: Yes/No | D24: For the provider request only. | E24: - | F24: No | G24: No | H24: No | I24: No | J24: No | K24: No
A25: SS.16 | B25: Notes | C25: text | D25: Decisions or assumptions for this service. | E25: -

Sheet 5 Search Demand
A1: 5 Search demand per environment
A2: One row per environment from the Setup sheet. Enter primary (not replicated) sizes.
A5: Environment | E5: Inputs | M5: Worked out
A6: Environment | B6: Search service | C6: Pega landscape | D6: Landscape rank (1-4) | E6: Input status (list) | F6: Searchable data today (GB) | G6: Documents today (count) | H6: Indexes (count) | I6: Primary shards per index (count) | J6: Annual growth (%) | K6: Planning period (years) | L6: Temporary extra data (GB) | M6: Searchable data at end of period (GB) | N6: Documents at end of period (count) | O6: Primary shards (count) | P6: Notes
A7: =IF('1 Setup'!B14="","",'1 Setup'!B14) | B7: =IF(AND('1 Setup'!E14="Yes",'1 Setup'!G14<>""),'1 Setup'!G14,"") | C7: =IF('1 Setup'!D14="","",'1 Setup'!D14) | D7: =IFERROR(MATCH(C7,LANDSCAPES,0),0) | E7: Example | F7: 5 | G7: 100000 | H7: 60 | I7: 1 | J7: 0.2 | K7: 3 | L7: 0 | M7: =F7*(1+J7)^K7 | N7: =G7*(1+J7)^K7 | O7: =H7*I7 | P7: Illustrative figures for the worked example. Replace with measured values.
A8: =IF('1 Setup'!B15="","",'1 Setup'!B15) | B8: =IF(AND('1 Setup'!E15="Yes",'1 Setup'!G15<>""),'1 Setup'!G15,"") | C8: =IF('1 Setup'!D15="","",'1 Setup'!D15) | D8: =IFERROR(MATCH(C8,LANDSCAPES,0),0) | E8: Example | F8: 10 | G8: 200000 | H8: 60 | I8: 1 | J8: 0.2 | K8: 3 | L8: 0 | M8: =F8*(1+J8)^K8 | N8: =G8*(1+J8)^K8 | O8: =H8*I8 | P8: Illustrative figures for the worked example. Replace with measured values.
A9: =IF('1 Setup'!B16="","",'1 Setup'!B16) | B9: =IF(AND('1 Setup'!E16="Yes",'1 Setup'!G16<>""),'1 Setup'!G16,"") | C9: =IF('1 Setup'!D16="","",'1 Setup'!D16) | D9: =IFERROR(MATCH(C9,LANDSCAPES,0),0) | E9: Example | F9: 15 | G9: 300000 | H9: 60 | I9: 1 | J9: 0.2 | K9: 3 | L9: 0 | M9: =F9*(1+J9)^K9 | N9: =G9*(1+J9)^K9 | O9: =H9*I9 | P9: Illustrative figures for the worked example. Replace with measured values.
A10: =IF('1 Setup'!B17="","",'1 Setup'!B17) | B10: =IF(AND('1 Setup'!E17="Yes",'1 Setup'!G17<>""),'1 Setup'!G17,"") | C10: =IF('1 Setup'!D17="","",'1 Setup'!D17) | D10: =IFERROR(MATCH(C10,LANDSCAPES,0),0) | E10: Example | F10: 40 | G10: 800000 | H10: 60 | I10: 1 | J10: 0.2 | K10: 3 | L10: 0 | M10: =F10*(1+J10)^K10 | N10: =G10*(1+J10)^K10 | O10: =H10*I10 | P10: Illustrative figures for the worked example. Replace with measured values.
A11: =IF('1 Setup'!B18="","",'1 Setup'!B18) | B11: =IF(AND('1 Setup'!E18="Yes",'1 Setup'!G18<>""),'1 Setup'!G18,"") | C11: =IF('1 Setup'!D18="","",'1 Setup'!D18) | D11: =IFERROR(MATCH(C11,LANDSCAPES,0),0) | E11: Example | F11: 40 | G11: 800000 | H11: 60 | I11: 1 | J11: 0.2 | K11: 3 | L11: 0 | M11: =F11*(1+J11)^K11 | N11: =G11*(1+J11)^K11 | O11: =H11*I11 | P11: Illustrative figures for the worked example. Replace with measured values.
A12: =IF('1 Setup'!B19="","",'1 Setup'!B19) | B12: =IF(AND('1 Setup'!E19="Yes",'1 Setup'!G19<>""),'1 Setup'!G19,"") | C12: =IF('1 Setup'!D19="","",'1 Setup'!D19) | D12: =IFERROR(MATCH(C12,LANDSCAPES,0),0) | E12: Example | F12: 40 | G12: 2000000 | H12: 60 | I12: 1 | J12: 0.2 | K12: 3 | L12: 0 | M12: =F12*(1+J12)^K12 | N12: =G12*(1+J12)^K12 | O12: =H12*I12 | P12: Illustrative figures for the worked example. Replace with measured values.
A13: =IF('1 Setup'!B20="","",'1 Setup'!B20) | B13: =IF(AND('1 Setup'!E20="Yes",'1 Setup'!G20<>""),'1 Setup'!G20,"") | C13: =IF('1 Setup'!D20="","",'1 Setup'!D20) | D13: =IFERROR(MATCH(C13,LANDSCAPES,0),0) | I13: 1 | M13: =F13*(1+J13)^K13 | N13: =G13*(1+J13)^K13 | O13: =H13*I13
A14: =IF('1 Setup'!B21="","",'1 Setup'!B21) | B14: =IF(AND('1 Setup'!E21="Yes",'1 Setup'!G21<>""),'1 Setup'!G21,"") | C14: =IF('1 Setup'!D21="","",'1 Setup'!D21) | D14: =IFERROR(MATCH(C14,LANDSCAPES,0),0) | I14: 1 | M14: =F14*(1+J14)^K14 | N14: =G14*(1+J14)^K14 | O14: =H14*I14
A16: Yellow cells are inputs; grey cells are worked out. Hover over a column heading for guidance and the source. Where a measured figure is given it replaces the estimate beside it.

Sheet 6 Kafka Sizing
A1: 6 Kafka sizing: Confluent Cloud cluster type, units and pricing quantities
A2: One column per Kafka cluster. Every figure is a formula; the 'How it is worked out' column and the Ref column explain each step. Green rows are the results.
A4: Step | B4: Item | C4: Unit | D4: How it is worked out | E4: Ref | F4: K1 | G4: K2 | H4: K3 | I4: K4 | J4: K5 | K4: K6
A5: A. Environments on this cluster
A6: K.01 | B6: Environments assigned | C6: count | D6: In-scope environments assigned to this cluster on the Setup sheet. | E6: - | F6: =COUNTIF(KD_CLUSTER,F$4) | G6: =COUNTIF(KD_CLUSTER,G$4) | H6: =COUNTIF(KD_CLUSTER,H$4) | I6: =COUNTIF(KD_CLUSTER,I$4) | J6: =COUNTIF(KD_CLUSTER,J$4) | K6: =COUNTIF(KD_CLUSTER,K$4)
A7: K.02 | B7: Environment codes | C7: text | E7: - | F7: =TRIM(IF('3 Kafka Demand'!$B$7=F$4,'3 Kafka Demand'!$A$7&" ","")&IF('3 Kafka Demand'!$B$8=F$4,'3 Kafka Demand'!$A$8&" ","")&IF('3 Kafka Demand'!$B$9=F$4,'3 Kafka Demand'!$A$9&" ","")&IF('3 Kafka Demand'!$B$10=F$4,'3 Kafka Demand'!$A$10&" ","")&IF('3 Kafka Demand'!$B$11=F$4,'3 Kafka Demand'!$A$11&" ","")&IF('3 Kafka Demand'!$B$12=F$4,'3 Kafka Demand'!$A$12&" ","")&IF('3 Kafka Demand'!$B$13=F$4,'3 Kafka Demand'!$A$13&" ","")&IF('3 Kafka Demand'!$B$14=F$4,'3 Kafka Demand'!$A$14&" ","")) | G7: =TRIM(IF('3 Kafka Demand'!$B$7=G$4,'3 Kafka Demand'!$A$7&" ","")&IF('3 Kafka Demand'!$B$8=G$4,'3 Kafka Demand'!$A$8&" ","")&IF('3 Kafka Demand'!$B$9=G$4,'3 Kafka Demand'!$A$9&" ","")&IF('3 Kafka Demand'!$B$10=G$4,'3 Kafka Demand'!$A$10&" ","")&IF('3 Kafka Demand'!$B$11=G$4,'3 Kafka Demand'!$A$11&" ","")&IF('3 Kafka Demand'!$B$12=G$4,'3 Kafka Demand'!$A$12&" ","")&IF('3 Kafka Demand'!$B$13=G$4,'3 Kafka Demand'!$A$13&" ","")&IF('3 Kafka Demand'!$B$14=G$4,'3 Kafka Demand'!$A$14&" ","")) | H7: =TRIM(IF('3 Kafka Demand'!$B$7=H$4,'3 Kafka Demand'!$A$7&" ","")&IF('3 Kafka Demand'!$B$8=H$4,'3 Kafka Demand'!$A$8&" ","")&IF('3 Kafka Demand'!$B$9=H$4,'3 Kafka Demand'!$A$9&" ","")&IF('3 Kafka Demand'!$B$10=H$4,'3 Kafka Demand'!$A$10&" ","")&IF('3 Kafka Demand'!$B$11=H$4,'3 Kafka Demand'!$A$11&" ","")&IF('3 Kafka Demand'!$B$12=H$4,'3 Kafka Demand'!$A$12&" ","")&IF('3 Kafka Demand'!$B$13=H$4,'3 Kafka Demand'!$A$13&" ","")&IF('3 Kafka Demand'!$B$14=H$4,'3 Kafka Demand'!$A$14&" ","")) | I7: =TRIM(IF('3 Kafka Demand'!$B$7=I$4,'3 Kafka Demand'!$A$7&" ","")&IF('3 Kafka Demand'!$B$8=I$4,'3 Kafka Demand'!$A$8&" ","")&IF('3 Kafka Demand'!$B$9=I$4,'3 Kafka Demand'!$A$9&" ","")&IF('3 Kafka Demand'!$B$10=I$4,'3 Kafka Demand'!$A$10&" ","")&IF('3 Kafka Demand'!$B$11=I$4,'3 Kafka Demand'!$A$11&" ","")&IF('3 Kafka Demand'!$B$12=I$4,'3 Kafka Demand'!$A$12&" ","")&IF('3 Kafka Demand'!$B$13=I$4,'3 Kafka Demand'!$A$13&" ","")&IF('3 Kafka Demand'!$B$14=I$4,'3 Kafka Demand'!$A$14&" ","")) | J7: =TRIM(IF('3 Kafka Demand'!$B$7=J$4,'3 Kafka Demand'!$A$7&" ","")&IF('3 Kafka Demand'!$B$8=J$4,'3 Kafka Demand'!$A$8&" ","")&IF('3 Kafka Demand'!$B$9=J$4,'3 Kafka Demand'!$A$9&" ","")&IF('3 Kafka Demand'!$B$10=J$4,'3 Kafka Demand'!$A$10&" ","")&IF('3 Kafka Demand'!$B$11=J$4,'3 Kafka Demand'!$A$11&" ","")&IF('3 Kafka Demand'!$B$12=J$4,'3 Kafka Demand'!$A$12&" ","")&IF('3 Kafka Demand'!$B$13=J$4,'3 Kafka Demand'!$A$13&" ","")&IF('3 Kafka Demand'!$B$14=J$4,'3 Kafka Demand'!$A$14&" ","")) | K7: =TRIM(IF('3 Kafka Demand'!$B$7=K$4,'3 Kafka Demand'!$A$7&" ","")&IF('3 Kafka Demand'!$B$8=K$4,'3 Kafka Demand'!$A$8&" ","")&IF('3 Kafka Demand'!$B$9=K$4,'3 Kafka Demand'!$A$9&" ","")&IF('3 Kafka Demand'!$B$10=K$4,'3 Kafka Demand'!$A$10&" ","")&IF('3 Kafka Demand'!$B$11=K$4,'3 Kafka Demand'!$A$11&" ","")&IF('3 Kafka Demand'!$B$12=K$4,'3 Kafka Demand'!$A$12&" ","")&IF('3 Kafka Demand'!$B$13=K$4,'3 Kafka Demand'!$A$13&" ","")&IF('3 Kafka Demand'!$B$14=K$4,'3 Kafka Demand'!$A$14&" ",""))
A8: K.03 | B8: Cluster name | C8: text | D8: From the Kafka Clusters sheet. | E8: - | F8: =IF('2 Kafka Clusters'!F6="",F$4,'2 Kafka Clusters'!F6) | G8: =IF('2 Kafka Clusters'!G6="",G$4,'2 Kafka Clusters'!G6) | H8: =IF('2 Kafka Clusters'!H6="",H$4,'2 Kafka Clusters'!H6) | I8: =IF('2 Kafka Clusters'!I6="",I$4,'2 Kafka Clusters'!I6) | J8: =IF('2 Kafka Clusters'!J6="",J$4,'2 Kafka Clusters'!J6) | K8: =IF('2 Kafka Clusters'!K6="",K$4,'2 Kafka Clusters'!K6)
A9: K.04 | B9: Most demanding landscape (rank) | C9: 1-4 | D9: 1 Development, 2 Testing, 3 Stage, 4 Production. | E9: - | F9: =SUMPRODUCT(MAX((KD_CLUSTER=F$4)*KD_RANK)) | G9: =SUMPRODUCT(MAX((KD_CLUSTER=G$4)*KD_RANK)) | H9: =SUMPRODUCT(MAX((KD_CLUSTER=H$4)*KD_RANK)) | I9: =SUMPRODUCT(MAX((KD_CLUSTER=I$4)*KD_RANK)) | J9: =SUMPRODUCT(MAX((KD_CLUSTER=J$4)*KD_RANK)) | K9: =SUMPRODUCT(MAX((KD_CLUSTER=K$4)*KD_RANK))
A10: K.05 | B10: Most demanding landscape | C10: text | E10: P1 | F10: =IF(F9=0,"-",INDEX(LANDSCAPES,F9)) | G10: =IF(G9=0,"-",INDEX(LANDSCAPES,G9)) | H10: =IF(H9=0,"-",INDEX(LANDSCAPES,H9)) | I10: =IF(I9=0,"-",INDEX(LANDSCAPES,I9)) | J10: =IF(J9=0,"-",INDEX(LANDSCAPES,J9)) | K10: =IF(K9=0,"-",INDEX(LANDSCAPES,K9))
A11: K.06 | B11: Pega Kafka sizing row used | C11: text | D11: Production or Stage use Pega's Production row; Testing or Development use the Development row (W). | E11: P1, W | F11: =IF(F9=0,"-",IF(F9>=3,"Production","Development")) | G11: =IF(G9=0,"-",IF(G9>=3,"Production","Development")) | H11: =IF(H9=0,"-",IF(H9>=3,"Production","Development")) | I11: =IF(I9=0,"-",IF(I9>=3,"Production","Development")) | J11: =IF(J9=0,"-",IF(J9>=3,"Production","Development")) | K11: =IF(K9=0,"-",IF(K9>=3,"Production","Development"))
A12: B. Demand: sum of the environments on this cluster (from the Kafka Demand sheet)
A13: K.07 | B13: Leader partitions | C13: count | D13: Sum of leader partitions. Confluent counts partitions before replication [C1]. | E13: C1, P3 | F13: =SUMIF(KD_CLUSTER,F$4,KD_PARTS) | G13: =SUMIF(KD_CLUSTER,G$4,KD_PARTS) | H13: =SUMIF(KD_CLUSTER,H$4,KD_PARTS) | I13: =SUMIF(KD_CLUSTER,I$4,KD_PARTS) | J13: =SUMIF(KD_CLUSTER,J$4,KD_PARTS) | K13: =SUMIF(KD_CLUSTER,K$4,KD_PARTS)
A14: K.08 | B14: Compacted partitions | C14: count | D14: Sum of compacted partitions. | E14: C1 | F14: =SUMIF(KD_CLUSTER,F$4,KD_COMPACT) | G14: =SUMIF(KD_CLUSTER,G$4,KD_COMPACT) | H14: =SUMIF(KD_CLUSTER,H$4,KD_COMPACT) | I14: =SUMIF(KD_CLUSTER,I$4,KD_COMPACT) | J14: =SUMIF(KD_CLUSTER,J$4,KD_COMPACT) | K14: =SUMIF(KD_CLUSTER,K$4,KD_COMPACT)
A15: K.09 | B15: Peak write (ingress) | C15: MBps | D15: Sum of environment peaks. This is cautious because the peaks may not happen at the same time. | E15: - | F15: =SUMIF(KD_CLUSTER,F$4,KD_IN) | G15: =SUMIF(KD_CLUSTER,G$4,KD_IN) | H15: =SUMIF(KD_CLUSTER,H$4,KD_IN) | I15: =SUMIF(KD_CLUSTER,I$4,KD_IN) | J15: =SUMIF(KD_CLUSTER,J$4,KD_IN) | K15: =SUMIF(KD_CLUSTER,K$4,KD_IN)
A16: K.10 | B16: Peak read (egress) | C16: MBps | D16: Sum of environment peaks. | E16: - | F16: =SUMIF(KD_CLUSTER,F$4,KD_OUT) | G16: =SUMIF(KD_CLUSTER,G$4,KD_OUT) | H16: =SUMIF(KD_CLUSTER,H$4,KD_OUT) | I16: =SUMIF(KD_CLUSTER,I$4,KD_OUT) | J16: =SUMIF(KD_CLUSTER,J$4,KD_OUT) | K16: =SUMIF(KD_CLUSTER,K$4,KD_OUT)
A17: K.11 | B17: Peak client connections | C17: count | D17: Sum of environment peaks. | E17: - | F17: =SUMIF(KD_CLUSTER,F$4,KD_CONN) | G17: =SUMIF(KD_CLUSTER,G$4,KD_CONN) | H17: =SUMIF(KD_CLUSTER,H$4,KD_CONN) | I17: =SUMIF(KD_CLUSTER,I$4,KD_CONN) | J17: =SUMIF(KD_CLUSTER,J$4,KD_CONN) | K17: =SUMIF(KD_CLUSTER,K$4,KD_CONN)
A18: K.12 | B18: Peak requests per second | C18: req/s | D18: Sum of environment peaks. | E18: - | F18: =SUMIF(KD_CLUSTER,F$4,KD_REQ) | G18: =SUMIF(KD_CLUSTER,G$4,KD_REQ) | H18: =SUMIF(KD_CLUSTER,H$4,KD_REQ) | I18: =SUMIF(KD_CLUSTER,I$4,KD_REQ) | J18: =SUMIF(KD_CLUSTER,J$4,KD_REQ) | K18: =SUMIF(KD_CLUSTER,K$4,KD_REQ)
A19: K.13 | B19: Largest message | C19: bytes | D19: Largest of the environment figures. | E19: - | F19: =SUMPRODUCT(MAX((KD_CLUSTER=F$4)*KD_MSGMAX)) | G19: =SUMPRODUCT(MAX((KD_CLUSTER=G$4)*KD_MSGMAX)) | H19: =SUMPRODUCT(MAX((KD_CLUSTER=H$4)*KD_MSGMAX)) | I19: =SUMPRODUCT(MAX((KD_CLUSTER=I$4)*KD_MSGMAX)) | J19: =SUMPRODUCT(MAX((KD_CLUSTER=J$4)*KD_MSGMAX)) | K19: =SUMPRODUCT(MAX((KD_CLUSTER=K$4)*KD_MSGMAX))
A20: K.14 | B20: GiB written per day | C20: GiB | D20: Sum of environments. | E20: - | F20: =SUMIF(KD_CLUSTER,F$4,KD_GIB) | G20: =SUMIF(KD_CLUSTER,G$4,KD_GIB) | H20: =SUMIF(KD_CLUSTER,H$4,KD_GIB) | I20: =SUMIF(KD_CLUSTER,I$4,KD_GIB) | J20: =SUMIF(KD_CLUSTER,J$4,KD_GIB) | K20: =SUMIF(KD_CLUSTER,K$4,KD_GIB)
A21: K.15 | B21: GiB read per day | C21: GiB | D21: Sum of environments. | E21: - | F21: =SUMIF(KD_CLUSTER,F$4,KD_GIBR) | G21: =SUMIF(KD_CLUSTER,G$4,KD_GIBR) | H21: =SUMIF(KD_CLUSTER,H$4,KD_GIBR) | I21: =SUMIF(KD_CLUSTER,I$4,KD_GIBR) | J21: =SUMIF(KD_CLUSTER,J$4,KD_GIBR) | K21: =SUMIF(KD_CLUSTER,K$4,KD_GIBR)
A22: K.16 | B22: Stored GiB before replication | C22: GiB | D22: Sum of environments (GiB per day x retention). | E22: - | F22: =SUMIF(KD_CLUSTER,F$4,KD_STORE) | G22: =SUMIF(KD_CLUSTER,G$4,KD_STORE) | H22: =SUMIF(KD_CLUSTER,H$4,KD_STORE) | I22: =SUMIF(KD_CLUSTER,I$4,KD_STORE) | J22: =SUMIF(KD_CLUSTER,J$4,KD_STORE) | K22: =SUMIF(KD_CLUSTER,K$4,KD_STORE)
A23: K.17 | B23: Environments with Example inputs | C23: count | E23: - | F23: =SUMPRODUCT((KD_CLUSTER=F$4)*(KD_STATUS="Example")) | G23: =SUMPRODUCT((KD_CLUSTER=G$4)*(KD_STATUS="Example")) | H23: =SUMPRODUCT((KD_CLUSTER=H$4)*(KD_STATUS="Example")) | I23: =SUMPRODUCT((KD_CLUSTER=I$4)*(KD_STATUS="Example")) | J23: =SUMPRODUCT((KD_CLUSTER=J$4)*(KD_STATUS="Example")) | K23: =SUMPRODUCT((KD_CLUSTER=K$4)*(KD_STATUS="Example"))
A24: K.18 | B24: Environments without an input status | C24: count | E24: - | F24: =SUMPRODUCT((KD_CLUSTER=F$4)*(KD_STATUS="")) | G24: =SUMPRODUCT((KD_CLUSTER=G$4)*(KD_STATUS="")) | H24: =SUMPRODUCT((KD_CLUSTER=H$4)*(KD_STATUS="")) | I24: =SUMPRODUCT((KD_CLUSTER=I$4)*(KD_STATUS="")) | J24: =SUMPRODUCT((KD_CLUSTER=J$4)*(KD_STATUS="")) | K24: =SUMPRODUCT((KD_CLUSTER=K$4)*(KD_STATUS=""))
A25: K.19 | B25: Environments without a connections figure | C25: count | E25: - | F25: =SUMPRODUCT((KD_CLUSTER=F$4)*(KD_CONN="")) | G25: =SUMPRODUCT((KD_CLUSTER=G$4)*(KD_CONN="")) | H25: =SUMPRODUCT((KD_CLUSTER=H$4)*(KD_CONN="")) | I25: =SUMPRODUCT((KD_CLUSTER=I$4)*(KD_CONN="")) | J25: =SUMPRODUCT((KD_CLUSTER=J$4)*(KD_CONN="")) | K25: =SUMPRODUCT((KD_CLUSTER=K$4)*(KD_CONN=""))
A26: K.20 | B26: Environments without a requests figure | C26: count | E26: - | F26: =SUMPRODUCT((KD_CLUSTER=F$4)*(KD_REQ="")) | G26: =SUMPRODUCT((KD_CLUSTER=G$4)*(KD_REQ="")) | H26: =SUMPRODUCT((KD_CLUSTER=H$4)*(KD_REQ="")) | I26: =SUMPRODUCT((KD_CLUSTER=I$4)*(KD_REQ="")) | J26: =SUMPRODUCT((KD_CLUSTER=J$4)*(KD_REQ="")) | K26: =SUMPRODUCT((KD_CLUSTER=K$4)*(KD_REQ=""))
A27: C. Planning allowance
A28: K.21 | B28: Growth allowance | C28: % | D28: From the Kafka Clusters sheet. | E28: W | F28: =IF('2 Kafka Clusters'!F16="",0,'2 Kafka Clusters'!F16) | G28: =IF('2 Kafka Clusters'!G16="",0,'2 Kafka Clusters'!G16) | H28: =IF('2 Kafka Clusters'!H16="",0,'2 Kafka Clusters'!H16) | I28: =IF('2 Kafka Clusters'!I16="",0,'2 Kafka Clusters'!I16) | J28: =IF('2 Kafka Clusters'!J16="",0,'2 Kafka Clusters'!J16) | K28: =IF('2 Kafka Clusters'!K16="",0,'2 Kafka Clusters'!K16)
A29: K.22 | B29: Target maximum utilisation | C29: % | D29: From the Kafka Clusters sheet. 70 % matches Pega's CPU action point. | E29: P5 | F29: =IF('2 Kafka Clusters'!F17="",P_CPU_ACT,'2 Kafka Clusters'!F17) | G29: =IF('2 Kafka Clusters'!G17="",P_CPU_ACT,'2 Kafka Clusters'!G17) | H29: =IF('2 Kafka Clusters'!H17="",P_CPU_ACT,'2 Kafka Clusters'!H17) | I29: =IF('2 Kafka Clusters'!I17="",P_CPU_ACT,'2 Kafka Clusters'!I17) | J29: =IF('2 Kafka Clusters'!J17="",P_CPU_ACT,'2 Kafka Clusters'!J17) | K29: =IF('2 Kafka Clusters'!K17="",P_CPU_ACT,'2 Kafka Clusters'!K17)
A30: K.23 | B30: Planning factor | C30: x | D30: (1 + growth) / target utilisation. | E30: W | F30: =IF(F29>0,(1+F28)/F29,0) | G30: =IF(G29>0,(1+G28)/G29,0) | H30: =IF(H29>0,(1+H28)/H29,0) | I30: =IF(I29>0,(1+I28)/I29,0) | J30: =IF(J29>0,(1+J28)/J29,0) | K30: =IF(K29>0,(1+K28)/K29,0)
A31: K.24 | B31: Planned leader partitions | C31: count | D31: Leader partitions x planning factor, rounded up. | E31: W | F31: =ROUNDUP(F13*F30,0) | G31: =ROUNDUP(G13*G30,0) | H31: =ROUNDUP(H13*H30,0) | I31: =ROUNDUP(I13*I30,0) | J31: =ROUNDUP(J13*J30,0) | K31: =ROUNDUP(K13*K30,0)
A32: K.25 | B32: Planned compacted partitions | C32: count | D32: Compacted partitions x planning factor, rounded up. | E32: W | F32: =ROUNDUP(F14*F30,0) | G32: =ROUNDUP(G14*G30,0) | H32: =ROUNDUP(H14*H30,0) | I32: =ROUNDUP(I14*I30,0) | J32: =ROUNDUP(J14*J30,0) | K32: =ROUNDUP(K14*K30,0)
A33: K.26 | B33: Planned ingress | C33: MBps | D33: Peak write x planning factor. | E33: W | F33: =F15*F30 | G33: =G15*G30 | H33: =H15*H30 | I33: =I15*I30 | J33: =J15*J30 | K33: =K15*K30
A34: K.27 | B34: Planned egress | C34: MBps | D34: Peak read x planning factor. | E34: W | F34: =F16*F30 | G34: =G16*G30 | H34: =H16*H30 | I34: =I16*I30 | J34: =J16*J30 | K34: =K16*K30
A35: K.28 | B35: Planned client connections | C35: count | D35: Connections x planning factor, rounded up. | E35: W | F35: =ROUNDUP(F17*F30,0) | G35: =ROUNDUP(G17*G30,0) | H35: =ROUNDUP(H17*H30,0) | I35: =ROUNDUP(I17*I30,0) | J35: =ROUNDUP(J17*J30,0) | K35: =ROUNDUP(K17*K30,0)
A36: K.29 | B36: Planned requests per second | C36: req/s | D36: Requests x planning factor, rounded up. | E36: W | F36: =ROUNDUP(F18*F30,0) | G36: =ROUNDUP(G18*G30,0) | H36: =ROUNDUP(H18*H30,0) | I36: =ROUNDUP(I18*I30,0) | J36: =ROUNDUP(J18*J30,0) | K36: =ROUNDUP(K18*K30,0)
A37: D. Requirements from the Kafka Clusters sheet
A38: K.30 | B38: Required SLA | C38: % | D38: Converted from the list choice. | E38: C1 | F38: =IFERROR(VALUE(SUBSTITUTE('2 Kafka Clusters'!F9,"%",""))/100,0) | G38: =IFERROR(VALUE(SUBSTITUTE('2 Kafka Clusters'!G9,"%",""))/100,0) | H38: =IFERROR(VALUE(SUBSTITUTE('2 Kafka Clusters'!H9,"%",""))/100,0) | I38: =IFERROR(VALUE(SUBSTITUTE('2 Kafka Clusters'!I9,"%",""))/100,0) | J38: =IFERROR(VALUE(SUBSTITUTE('2 Kafka Clusters'!J9,"%",""))/100,0) | K38: =IFERROR(VALUE(SUBSTITUTE('2 Kafka Clusters'!K9,"%",""))/100,0)
A39: K.31 | B39: Private networking | C39: Yes/No | E39: C1 | F39: =IF('2 Kafka Clusters'!F10="","No",'2 Kafka Clusters'!F10) | G39: =IF('2 Kafka Clusters'!G10="","No",'2 Kafka Clusters'!G10) | H39: =IF('2 Kafka Clusters'!H10="","No",'2 Kafka Clusters'!H10) | I39: =IF('2 Kafka Clusters'!I10="","No",'2 Kafka Clusters'!I10) | J39: =IF('2 Kafka Clusters'!J10="","No",'2 Kafka Clusters'!J10) | K39: =IF('2 Kafka Clusters'!K10="","No",'2 Kafka Clusters'!K10)
A40: K.32 | B40: Self-managed keys | C40: Yes/No | E40: C4 | F40: =IF('2 Kafka Clusters'!F11="","No",'2 Kafka Clusters'!F11) | G40: =IF('2 Kafka Clusters'!G11="","No",'2 Kafka Clusters'!G11) | H40: =IF('2 Kafka Clusters'!H11="","No",'2 Kafka Clusters'!H11) | I40: =IF('2 Kafka Clusters'!I11="","No",'2 Kafka Clusters'!I11) | J40: =IF('2 Kafka Clusters'!J11="","No",'2 Kafka Clusters'!J11) | K40: =IF('2 Kafka Clusters'!K11="","No",'2 Kafka Clusters'!K11)
A41: K.33 | B41: Multi-zone (Dedicated) | C41: Yes/No | E41: C1 | F41: =IF('2 Kafka Clusters'!F12="","Yes",'2 Kafka Clusters'!F12) | G41: =IF('2 Kafka Clusters'!G12="","Yes",'2 Kafka Clusters'!G12) | H41: =IF('2 Kafka Clusters'!H12="","Yes",'2 Kafka Clusters'!H12) | I41: =IF('2 Kafka Clusters'!I12="","Yes",'2 Kafka Clusters'!I12) | J41: =IF('2 Kafka Clusters'!J12="","Yes",'2 Kafka Clusters'!J12) | K41: =IF('2 Kafka Clusters'!K12="","Yes",'2 Kafka Clusters'!K12)
...

Sheet 7 Search Sizing
A1: 7 Search sizing: managed OpenSearch nodes, storage and SRS
A2: One column per search service. Pega's tables give the starting size; storage, shard and replica rules can raise the data-node count. Green rows are the results.
A4: Step | B4: Item | C4: Unit | D4: How it is worked out | E4: Ref | F4: S1 | G4: S2 | H4: S3 | I4: S4 | J4: S5 | K4: S6
A5: A. Environments on this service
A6: S.01 | B6: Environments assigned | C6: count | D6: In-scope environments assigned to this service. | E6: - | F6: =COUNTIF(SD_SVC,F$4) | G6: =COUNTIF(SD_SVC,G$4) | H6: =COUNTIF(SD_SVC,H$4) | I6: =COUNTIF(SD_SVC,I$4) | J6: =COUNTIF(SD_SVC,J$4) | K6: =COUNTIF(SD_SVC,K$4)
A7: S.02 | B7: Environment codes | C7: text | E7: - | F7: =TRIM(IF('5 Search Demand'!$B$7=F$4,'5 Search Demand'!$A$7&" ","")&IF('5 Search Demand'!$B$8=F$4,'5 Search Demand'!$A$8&" ","")&IF('5 Search Demand'!$B$9=F$4,'5 Search Demand'!$A$9&" ","")&IF('5 Search Demand'!$B$10=F$4,'5 Search Demand'!$A$10&" ","")&IF('5 Search Demand'!$B$11=F$4,'5 Search Demand'!$A$11&" ","")&IF('5 Search Demand'!$B$12=F$4,'5 Search Demand'!$A$12&" ","")&IF('5 Search Demand'!$B$13=F$4,'5 Search Demand'!$A$13&" ","")&IF('5 Search Demand'!$B$14=F$4,'5 Search Demand'!$A$14&" ","")) | G7: =TRIM(IF('5 Search Demand'!$B$7=G$4,'5 Search Demand'!$A$7&" ","")&IF('5 Search Demand'!$B$8=G$4,'5 Search Demand'!$A$8&" ","")&IF('5 Search Demand'!$B$9=G$4,'5 Search Demand'!$A$9&" ","")&IF('5 Search Demand'!$B$10=G$4,'5 Search Demand'!$A$10&" ","")&IF('5 Search Demand'!$B$11=G$4,'5 Search Demand'!$A$11&" ","")&IF('5 Search Demand'!$B$12=G$4,'5 Search Demand'!$A$12&" ","")&IF('5 Search Demand'!$B$13=G$4,'5 Search Demand'!$A$13&" ","")&IF('5 Search Demand'!$B$14=G$4,'5 Search Demand'!$A$14&" ","")) | H7: =TRIM(IF('5 Search Demand'!$B$7=H$4,'5 Search Demand'!$A$7&" ","")&IF('5 Search Demand'!$B$8=H$4,'5 Search Demand'!$A$8&" ","")&IF('5 Search Demand'!$B$9=H$4,'5 Search Demand'!$A$9&" ","")&IF('5 Search Demand'!$B$10=H$4,'5 Search Demand'!$A$10&" ","")&IF('5 Search Demand'!$B$11=H$4,'5 Search Demand'!$A$11&" ","")&IF('5 Search Demand'!$B$12=H$4,'5 Search Demand'!$A$12&" ","")&IF('5 Search Demand'!$B$13=H$4,'5 Search Demand'!$A$13&" ","")&IF('5 Search Demand'!$B$14=H$4,'5 Search Demand'!$A$14&" ","")) | I7: =TRIM(IF('5 Search Demand'!$B$7=I$4,'5 Search Demand'!$A$7&" ","")&IF('5 Search Demand'!$B$8=I$4,'5 Search Demand'!$A$8&" ","")&IF('5 Search Demand'!$B$9=I$4,'5 Search Demand'!$A$9&" ","")&IF('5 Search Demand'!$B$10=I$4,'5 Search Demand'!$A$10&" ","")&IF('5 Search Demand'!$B$11=I$4,'5 Search Demand'!$A$11&" ","")&IF('5 Search Demand'!$B$12=I$4,'5 Search Demand'!$A$12&" ","")&IF('5 Search Demand'!$B$13=I$4,'5 Search Demand'!$A$13&" ","")&IF('5 Search Demand'!$B$14=I$4,'5 Search Demand'!$A$14&" ","")) | J7: =TRIM(IF('5 Search Demand'!$B$7=J$4,'5 Search Demand'!$A$7&" ","")&IF('5 Search Demand'!$B$8=J$4,'5 Search Demand'!$A$8&" ","")&IF('5 Search Demand'!$B$9=J$4,'5 Search Demand'!$A$9&" ","")&IF('5 Search Demand'!$B$10=J$4,'5 Search Demand'!$A$10&" ","")&IF('5 Search Demand'!$B$11=J$4,'5 Search Demand'!$A$11&" ","")&IF('5 Search Demand'!$B$12=J$4,'5 Search Demand'!$A$12&" ","")&IF('5 Search Demand'!$B$13=J$4,'5 Search Demand'!$A$13&" ","")&IF('5 Search Demand'!$B$14=J$4,'5 Search Demand'!$A$14&" ","")) | K7: =TRIM(IF('5 Search Demand'!$B$7=K$4,'5 Search Demand'!$A$7&" ","")&IF('5 Search Demand'!$B$8=K$4,'5 Search Demand'!$A$8&" ","")&IF('5 Search Demand'!$B$9=K$4,'5 Search Demand'!$A$9&" ","")&IF('5 Search Demand'!$B$10=K$4,'5 Search Demand'!$A$10&" ","")&IF('5 Search Demand'!$B$11=K$4,'5 Search Demand'!$A$11&" ","")&IF('5 Search Demand'!$B$12=K$4,'5 Search Demand'!$A$12&" ","")&IF('5 Search Demand'!$B$13=K$4,'5 Search Demand'!$A$13&" ","")&IF('5 Search Demand'!$B$14=K$4,'5 Search Demand'!$A$14&" ",""))
A8: S.03 | B8: Service name | C8: text | E8: - | F8: =IF('4 Search Services'!F6="",F$4,'4 Search Services'!F6) | G8: =IF('4 Search Services'!G6="",G$4,'4 Search Services'!G6) | H8: =IF('4 Search Services'!H6="",H$4,'4 Search Services'!H6) | I8: =IF('4 Search Services'!I6="",I$4,'4 Search Services'!I6) | J8: =IF('4 Search Services'!J6="",J$4,'4 Search Services'!J6) | K8: =IF('4 Search Services'!K6="",K$4,'4 Search Services'!K6)
A9: S.04 | B9: Most demanding landscape (rank) | C9: 1-4 | E9: - | F9: =SUMPRODUCT(MAX((SD_SVC=F$4)*SD_RANK)) | G9: =SUMPRODUCT(MAX((SD_SVC=G$4)*SD_RANK)) | H9: =SUMPRODUCT(MAX((SD_SVC=H$4)*SD_RANK)) | I9: =SUMPRODUCT(MAX((SD_SVC=I$4)*SD_RANK)) | J9: =SUMPRODUCT(MAX((SD_SVC=J$4)*SD_RANK)) | K9: =SUMPRODUCT(MAX((SD_SVC=K$4)*SD_RANK))
A10: S.05 | B10: Most demanding landscape | C10: text | E10: P2 | F10: =IF(F9=0,"-",INDEX(LANDSCAPES,F9)) | G10: =IF(G9=0,"-",INDEX(LANDSCAPES,G9)) | H10: =IF(H9=0,"-",INDEX(LANDSCAPES,H9)) | I10: =IF(I9=0,"-",INDEX(LANDSCAPES,I9)) | J10: =IF(J9=0,"-",INDEX(LANDSCAPES,J9)) | K10: =IF(K9=0,"-",INDEX(LANDSCAPES,K9))
A11: S.06 | B11: Pega table rows used | C11: text | D11: Prod = 'Production, Stage'; Test = 'Testing, Development'. | E11: P2 | F11: =IF(F9=0,"-",IF(F9>=3,"Prod","Test")) | G11: =IF(G9=0,"-",IF(G9>=3,"Prod","Test")) | H11: =IF(H9=0,"-",IF(H9>=3,"Prod","Test")) | I11: =IF(I9=0,"-",IF(I9>=3,"Prod","Test")) | J11: =IF(J9=0,"-",IF(J9>=3,"Prod","Test")) | K11: =IF(K9=0,"-",IF(K9>=3,"Prod","Test"))
A12: B. Demand: sum of the environments on this service (from the Search Demand sheet)
A13: S.07 | B13: Searchable data today | C13: GB | E13: - | F13: =SUMIF(SD_SVC,F$4,SD_GB) | G13: =SUMIF(SD_SVC,G$4,SD_GB) | H13: =SUMIF(SD_SVC,H$4,SD_GB) | I13: =SUMIF(SD_SVC,I$4,SD_GB) | J13: =SUMIF(SD_SVC,J$4,SD_GB) | K13: =SUMIF(SD_SVC,K$4,SD_GB)
A14: S.08 | B14: Searchable data at end of period | C14: GB | D14: Sum of each environment's grown figure. | E14: - | F14: =SUMIF(SD_SVC,F$4,SD_FGB) | G14: =SUMIF(SD_SVC,G$4,SD_FGB) | H14: =SUMIF(SD_SVC,H$4,SD_FGB) | I14: =SUMIF(SD_SVC,I$4,SD_FGB) | J14: =SUMIF(SD_SVC,J$4,SD_FGB) | K14: =SUMIF(SD_SVC,K$4,SD_FGB)
A15: S.09 | B15: Temporary extra data | C15: GB | E15: - | F15: =SUMIF(SD_SVC,F$4,SD_TMP) | G15: =SUMIF(SD_SVC,G$4,SD_TMP) | H15: =SUMIF(SD_SVC,H$4,SD_TMP) | I15: =SUMIF(SD_SVC,I$4,SD_TMP) | J15: =SUMIF(SD_SVC,J$4,SD_TMP) | K15: =SUMIF(SD_SVC,K$4,SD_TMP)
A16: S.10 | B16: Documents at end of period | C16: count | E16: - | F16: =SUMIF(SD_SVC,F$4,SD_FDOCS) | G16: =SUMIF(SD_SVC,G$4,SD_FDOCS) | H16: =SUMIF(SD_SVC,H$4,SD_FDOCS) | I16: =SUMIF(SD_SVC,I$4,SD_FDOCS) | J16: =SUMIF(SD_SVC,J$4,SD_FDOCS) | K16: =SUMIF(SD_SVC,K$4,SD_FDOCS)
A17: S.11 | B17: Indexes | C17: count | E17: - | F17: =SUMIF(SD_SVC,F$4,SD_IDX) | G17: =SUMIF(SD_SVC,G$4,SD_IDX) | H17: =SUMIF(SD_SVC,H$4,SD_IDX) | I17: =SUMIF(SD_SVC,I$4,SD_IDX) | J17: =SUMIF(SD_SVC,J$4,SD_IDX) | K17: =SUMIF(SD_SVC,K$4,SD_IDX)
A18: S.12 | B18: Primary shards | C18: count | E18: - | F18: =SUMIF(SD_SVC,F$4,SD_PRIM) | G18: =SUMIF(SD_SVC,G$4,SD_PRIM) | H18: =SUMIF(SD_SVC,H$4,SD_PRIM) | I18: =SUMIF(SD_SVC,I$4,SD_PRIM) | J18: =SUMIF(SD_SVC,J$4,SD_PRIM) | K18: =SUMIF(SD_SVC,K$4,SD_PRIM)
A19: S.13 | B19: Environments with Example inputs | C19: count | E19: - | F19: =SUMPRODUCT((SD_SVC=F$4)*(SD_STATUS="Example")) | G19: =SUMPRODUCT((SD_SVC=G$4)*(SD_STATUS="Example")) | H19: =SUMPRODUCT((SD_SVC=H$4)*(SD_STATUS="Example")) | I19: =SUMPRODUCT((SD_SVC=I$4)*(SD_STATUS="Example")) | J19: =SUMPRODUCT((SD_SVC=J$4)*(SD_STATUS="Example")) | K19: =SUMPRODUCT((SD_SVC=K$4)*(SD_STATUS="Example"))
A20: S.14 | B20: Environments without an input status | C20: count | E20: - | F20: =SUMPRODUCT((SD_SVC=F$4)*(SD_STATUS="")) | G20: =SUMPRODUCT((SD_SVC=G$4)*(SD_STATUS="")) | H20: =SUMPRODUCT((SD_SVC=H$4)*(SD_STATUS="")) | I20: =SUMPRODUCT((SD_SVC=I$4)*(SD_STATUS="")) | J20: =SUMPRODUCT((SD_SVC=J$4)*(SD_STATUS="")) | K20: =SUMPRODUCT((SD_SVC=K$4)*(SD_STATUS=""))
A21: C. Requirements from the Search Services sheet
A22: S.15 | B22: High availability | C22: Yes/No | E22: P2 | F22: =IF('4 Search Services'!F9="","Yes",'4 Search Services'!F9) | G22: =IF('4 Search Services'!G9="","Yes",'4 Search Services'!G9) | H22: =IF('4 Search Services'!H9="","Yes",'4 Search Services'!H9) | I22: =IF('4 Search Services'!I9="","Yes",'4 Search Services'!I9) | J22: =IF('4 Search Services'!J9="","Yes",'4 Search Services'!J9) | K22: =IF('4 Search Services'!K9="","Yes",'4 Search Services'!K9)
A23: S.16 | B23: Availability zones | C23: count | E23: O1 | F23: =IF('4 Search Services'!F10="",3,'4 Search Services'!F10) | G23: =IF('4 Search Services'!G10="",3,'4 Search Services'!G10) | H23: =IF('4 Search Services'!H10="",3,'4 Search Services'!H10) | I23: =IF('4 Search Services'!I10="",3,'4 Search Services'!I10) | J23: =IF('4 Search Services'!J10="",3,'4 Search Services'!J10) | K23: =IF('4 Search Services'!K10="",3,'4 Search Services'!K10)
A24: S.17 | B24: Replicas per primary | C24: count | E24: O2 | F24: =IF('4 Search Services'!F11="",1,'4 Search Services'!F11) | G24: =IF('4 Search Services'!G11="",1,'4 Search Services'!G11) | H24: =IF('4 Search Services'!H11="",1,'4 Search Services'!H11) | I24: =IF('4 Search Services'!I11="",1,'4 Search Services'!I11) | J24: =IF('4 Search Services'!J11="",1,'4 Search Services'!J11) | K24: =IF('4 Search Services'!K11="",1,'4 Search Services'!K11)
A25: S.18 | B25: Provider storage overhead | C25: % | E25: A1 | F25: =IF('4 Search Services'!F14="",A_SVC_OVH,'4 Search Services'!F14) | G25: =IF('4 Search Services'!G14="",A_SVC_OVH,'4 Search Services'!G14) | H25: =IF('4 Search Services'!H14="",A_SVC_OVH,'4 Search Services'!H14) | I25: =IF('4 Search Services'!I14="",A_SVC_OVH,'4 Search Services'!I14) | J25: =IF('4 Search Services'!J14="",A_SVC_OVH,'4 Search Services'!J14) | K25: =IF('4 Search Services'!K14="",A_SVC_OVH,'4 Search Services'!K14)
A26: S.19 | B26: Operating system reserve | C26: % | E26: A1 | F26: =IF('4 Search Services'!F15="",A_LINUX,'4 Search Services'!F15) | G26: =IF('4 Search Services'!G15="",A_LINUX,'4 Search Services'!G15) | H26: =IF('4 Search Services'!H15="",A_LINUX,'4 Search Services'!H15) | I26: =IF('4 Search Services'!I15="",A_LINUX,'4 Search Services'!I15) | J26: =IF('4 Search Services'!J15="",A_LINUX,'4 Search Services'!J15) | K26: =IF('4 Search Services'!K15="",A_LINUX,'4 Search Services'!K15)
A27: S.20 | B27: Indexing overhead | C27: % | E27: A1 | F27: =IF('4 Search Services'!F16="",A_INDEX_OVH,'4 Search Services'!F16) | G27: =IF('4 Search Services'!G16="",A_INDEX_OVH,'4 Search Services'!G16) | H27: =IF('4 Search Services'!H16="",A_INDEX_OVH,'4 Search Services'!H16) | I27: =IF('4 Search Services'!I16="",A_INDEX_OVH,'4 Search Services'!I16) | J27: =IF('4 Search Services'!J16="",A_INDEX_OVH,'4 Search Services'!J16) | K27: =IF('4 Search Services'!K16="",A_INDEX_OVH,'4 Search Services'!K16)
A28: D. Pega sizing profile
A29: S.21 | B29: Profile by the workbook rule | C29: text | D29: Large when searchable data at the end of the period reaches the 2 TB of Pega's large example, otherwise Default (W). Document count is reported in the checks. | E29: P2, W | F29: =IF(F6=0,"-",IF(F14>=P_SEARCH_LARGE_GB,"Large","Default")) | G29: =IF(G6=0,"-",IF(G14>=P_SEARCH_LARGE_GB,"Large","Default")) | H29: =IF(H6=0,"-",IF(H14>=P_SEARCH_LARGE_GB,"Large","Default")) | I29: =IF(I6=0,"-",IF(I14>=P_SEARCH_LARGE_GB,"Large","Default")) | J29: =IF(J6=0,"-",IF(J14>=P_SEARCH_LARGE_GB,"Large","Default")) | K29: =IF(K6=0,"-",IF(K14>=P_SEARCH_LARGE_GB,"Large","Default"))
A30: S.22 | B30: Profile used | C30: text | D30: The override on the Search Services sheet, if set. | E30: P2 | F30: =IF(F6=0,"-",IF(OR('4 Search Services'!F12="",'4 Search Services'!F12="Auto"),F29,'4 Search Services'!F12)) | G30: =IF(G6=0,"-",IF(OR('4 Search Services'!G12="",'4 Search Services'!G12="Auto"),G29,'4 Search Services'!G12)) | H30: =IF(H6=0,"-",IF(OR('4 Search Services'!H12="",'4 Search Services'!H12="Auto"),H29,'4 Search Services'!H12)) | I30: =IF(I6=0,"-",IF(OR('4 Search Services'!I12="",'4 Search Services'!I12="Auto"),I29,'4 Search Services'!I12)) | J30: =IF(J6=0,"-",IF(OR('4 Search Services'!J12="",'4 Search Services'!J12="Auto"),J29,'4 Search Services'!J12)) | K30: =IF(K6=0,"-",IF(OR('4 Search Services'!K12="",'4 Search Services'!K12="Auto"),K29,'4 Search Services'!K12))
